Workbook

Sheet Paramètres
B2: DEVIS — MISSION DE CONSEIL TECHNIQUE
B3: Faisabilité de principe et préparation du dossier Orange · v2.0
B5: PRINCIPE DE CHIFFRAGE
B6: Avant Orange, on ne facture que ce qui est nécessaire pour obtenir et réussir le rendez-vous. Le détail vient après, quand on sait de quoi on parle.
B9: LÉGENDE
B10: Cellules JAUNES | C10: à modifier | D10: Les seules cellules à éditer. Tout le reste est calculé.
B11: Texte bleu | D11: Saisie / hypothèse
B12: Texte noir | D12: Formule — ne pas écraser
B13: Texte vert | D13: Lien vers une autre feuille
B15: PARAMÈTRES
B16: TJM retenu (TND / jour) | C16: 700 | D16: Tarif Senior recommandé. Grille : 450 confirmé / 700 senior / 900 expert télécom. Trois méthodes convergentes justifient 700 — voir docs/25.
B17: Taux de TVA | C17: 0.19 | D17: Taux normal Tunisie 2026. Professions libérales passées de 13 % à 19 %. À confirmer avec un expert-comptable.
B18: Retenue à la source | C18: 0.1 | D18: 10 % en régime réel, 15 % en forfaitaire, calculée sur le HT. À confirmer avec un expert-comptable.
B19: Taux de change EUR/TND | C19: 3.373 | D19: Banque Centrale de Tunisie, 15/09/2026. Information seulement.
B22: CE QUE CE DEVIS NE COUVRE PAS
B23: — Développement de la plateforme Call Com (mission distincte — ~80 % développable sans Orange)
B24: — Réalisation du POC (la Phase 1 le spécifie, elle ne l'exécute pas)
B25: — Conseil juridique et réglementaire (la mission identifie les sujets et dit qui les porte)
B26: — Négociation commerciale avec Orange (partage de revenus, contrat, exclusivité)
B27: — Prospection des annonceurs
B28: — Développements côté Orange
B29: — Frais de déplacement hors Grand Tunis (refacturés au réel)
B30: — AUCUNE obligation de résultat sur la décision d'Orange — mission de moyens

Sheet Devis
B2: DEVIS DÉTAILLÉ PAR PHASE
B3: Montants en dinars tunisiens, hors taxes | E3: TJM : | F3: =Paramètres!C16
B5: Réf. | C5: Tâche | D5: Jours | E5: Montant HT | F5: Équiv. EUR | G5: Mode
B6: PHASE 1 — AVANT ORANGE · forfait · 3 à 4 semaines
B7: P1.1 | C7: Cadrage : concept, contraintes, objectif du rendez-vous | D7: 0.5 | E7: =D7*$F$3 | F7: =E7/Paramètres!$C$19 | G7: forfait
B8: P1.2 | C8: Note de faisabilité technique — ce qui est certain, ce qui est hypothèse, ce qui est à confirmer | D8: 2 | E8: =D8*$F$3 | F8: =E8/Paramètres!$C$19 | G8: forfait
B9: P1.3 | C9: Architecture conceptuelle Call Com + frontière Call Com / opérateur | D9: 1.5 | E9: =D9*$F$3 | F9: =E9/Paramètres!$C$19 | G9: forfait
B10: P1.4 | C10: Scénarios d'intégration possibles + flux d'appel et insertion de l'annonce | D10: 1.5 | E10: =D10*$F$3 | F10: =E10/Paramètres!$C$19 | G10: forfait
B11: P1.5 | C11: Sécurité, données personnelles, anti-fraude — grandes lignes | D11: 1 | E11: =D11*$F$3 | F11: =E11/Paramètres!$C$19 | G11: forfait
B12: P1.6 | C12: POC réalisable — périmètre minimal et critères de succès | D12: 0.5 | E12: =D12*$F$3 | F12: =E12/Paramètres!$C$19 | G12: forfait
B13: P1.7 | C13: Questions techniques à poser aux ingénieurs Orange | D13: 1 | E13: =D13*$F$3 | F13: =E13/Paramètres!$C$19 | G13: forfait
B14: P1.8 | C14: Consolidation du dossier + pitch 5 min + deck technique | D14: 1.5 | E14: =D14*$F$3 | F14: =E14/Paramètres!$C$19 | G14: forfait
C15: TOTAL PHASE 1 | D15: =SUM(D7,D8,D9,D10,D11,D12,D13,D14) | E15: =SUM(E7,E8,E9,E10,E11,E12,E13,E14) | F15: =E15/Paramètres!$C$19
B17: PHASE 2 — PREMIER ÉCHANGE AVEC ORANGE · forfait par cycle de réunion
B18: P2.1 | C18: Préparation et répétition du rendez-vous | D18: 1 | E18: =D18*$F$3 | F18: =E18/Paramètres!$C$19 | G18: forfait
B19: P2.2 | C19: Animation du rendez-vous aux côtés de Call Com | D19: 1 | E19: =D19*$F$3 | F19: =E19/Paramètres!$C$19 | G19: forfait
B20: P2.3 | C20: Compte rendu + note de décision d'architecture | D20: 1 | E20: =D20*$F$3 | F20: =E20/Paramètres!$C$19 | G20: forfait
C21: TOTAL PHASE 2 (par cycle) | D21: =SUM(D18,D19,D20) | E21: =SUM(E18,E19,E20) | F21: =E21/Paramètres!$C$19
B23: TICKET D'ENTRÉE · ce qui est engagé aujourd'hui
C24: Phase 1 + Phase 2 | D24: =D15+D21 | E24: =E15+E21 | F24: =E24/Paramètres!$C$19
C25: Montant hors taxes | E25: =E24 | F25: =E25/Paramètres!$C$19
C26: TVA | E26: =E24*Paramètres!$C$17 | F26: =E26/Paramètres!$C$19
C27: TOTAL TTC FACTURÉ | E27: =E24+E26 | F27: =E27/Paramètres!$C$19
C28: Retenue à la source (acompte d'impôt, sur le HT) | E28: =-E24*Paramètres!$C$18 | F28: =E28/Paramètres!$C$19
C29: ENCAISSÉ À LA FACTURATION | E29: =E27+E28 | F29: =E29/Paramètres!$C$19
B31: PHASE 3 — APRÈS ORANGE · CONDITIONNELLE, NON ENGAGÉE AUJOURD'HUI
C32: Le contenu dépend des réponses d'Orange. Un cadrage d'une journée, après la réunion, fixe périmètre et prix fermes.
C33: Scénario | D33: Jours | E33: Montant min | F33: Montant max | G33: Déclencheur
C34: Cadrage de Phase 3 (systématique) | D34: 1 | E34: =1*$F$3 | F34: =1*$F$3 | G34: après la réunion
C35: A — intégration simple | D35: 12-15 | E35: =12*$F$3 | F35: =15*$F$3 | G35: pré-provisionnement accepté
C36: B — intégration complexe | D36: 20-25 | E36: =20*$F$3 | F36: =25*$F$3 | G36: temps réel ou composant hébergé
C37: C — Orange ne donne pas suite | D37: 4-6 | E37: =4*$F$3 | F37: =6*$F$3 | G37: décline ou sans réponse
B39: OPTIONS
C40: Variante allégée de la Phase 1 (P1.1, P1.2 réduit, P1.4, P1.6, P1.7, P1.8) | D40: 6 | E40: =D40*$F$3 | F40: =E40/Paramètres!$C$19 | G40: forfait
C41: Réunion Orange supplémentaire (prépa + animation + CR allégé) | D41: 1.5 | E41: =D41*$F$3 | F41: =E41/Paramètres!$C$19 | G41: à l'unité
C42: Abonnement d'accompagnement — 3 jours par mois | D42: 3 | E42: =D42*$F$3 | F42: =E42/Paramètres!$C$19 | G42: par mois
B44: ÉCHÉANCIER DE PAIEMENT — sur le ticket d'entrée
C45: À la commande | D45: 0.5 | E45: =D45*$E$24
C46: À la remise du dossier de Phase 1 | D46: 0.3 | E46: =D46*$E$24
C47: Après la réunion Orange et son compte rendu | D47: 0.2 | E47: =D47*$E$24
...

Sheet Comparatif et repères
B2: SENSIBILITÉ AU TARIF ET REPÈRES DE MARCHÉ
B3: La colonne surlignée est le tarif appliqué dans l'onglet Devis
B5: Formule | C5: Jours | D5: 450 TND/j | E5: 700 TND/j | F5: 900 TND/j
B6: Phase 1 seule | C6: 9.5 | D6: =$C6*450 | E6: =$C6*700 | F6: =$C6*900
B7: Phase 1 allégée + Phase 2 | C7: 9 | D7: =$C7*450 | E7: =$C7*700 | F7: =$C7*900
B8: Phase 1 + Phase 2 (ticket d'entrée) | C8: 12.5 | D8: =$C8*450 | E8: =$C8*700 | F8: =$C8*900
B9: Phase 3 scénario A (bas de fourchette) | C9: 12 | D9: =$C9*450 | E9: =$C9*700 | F9: =$C9*900
B10: Phase 3 scénario B (bas de fourchette) | C10: 20 | D10: =$C10*450 | E10: =$C10*700 | F10: =$C10*900
B12: COMPARAISON AVEC LA VERSION 1.0 DU CHIFFRAGE
B13: Avant Orange — version 1.0 | C13: 30.5 | E13: =C13*Paramètres!$C$16
B14: Avant Orange — version 2.0 | C14: 12.5 | E14: =C14*Paramètres!$C$16
B15: Réduction | C15: =C14/C13-1 | E15: =E14-E13
B18: ABONNEMENT D'ACCOMPAGNEMENT
B19: La durée de cette phase dépend d'Orange, pas de vous : ne jamais la forfaitiser.
B20: 2 jours par mois | C20: 2 | E20: =C20*Paramètres!$C$16
B21: 3 jours par mois | C21: 3 | E21: =C21*Paramètres!$C$16
B22: 4 jours par mois | C22: 4 | E22: =C22*Paramètres!$C$16
B25: REPÈRES DE MARCHÉ 2026 (sources dans docs/25-chiffrage-mission.md)
B26: Freelance développeur, Tunisie | D26: 180 à 500 TND/j
B27: Expert spécialisé, contrats européens | D27: jusqu'à 750 TND/j
B28: Architecte cloud / solution senior, salaire | D28: > 7 000 TND/mois
B29: Coût employeur équivalent | D29: ~500 TND/jour ouvré
B30: Expert IT / logiciel, Europe | D30: 629 € ≈ 2 122 TND/j
B31: Décote nearshore Tunisie vs France | D31: −30 à −50 %
